<?xml version="1.0"?>
<sdf version="1.6">
  <world name='default'>
    <light name='sun' type='directional'>
      <cast_shadows>1</cast_shadows>
      <pose frame=''>0 0 10 0 -0 0</pose>
      <diffuse>0.8 0.8 0.8 1</diffuse>
      <specular>0.1 0.1 0.1 1</specular>
      <attenuation>
        <range>1000</range>
        <constant>0.9</constant>
        <linear>0.01</linear>
        <quadratic>0.001</quadratic>
      </attenuation>
      <direction>-0.5 0.5 -1</direction>
    </light>
    <gravity>0 0 0</gravity>
    <magnetic_field>6e-06 2.3e-05 -4.2e-05</magnetic_field>
    <atmosphere type='adiabatic'/>
    <physics name='default_physics' default='0' type='ode'>
      <max_step_size>0.001</max_step_size>
      <real_time_factor>1</real_time_factor>
      <real_time_update_rate>1000</real_time_update_rate>
    </physics>
    <scene>
      <ambient>0.4 0.4 0.4 1</ambient>
      <background>0.7 0.7 0.7 1</background>
      <shadows>1</shadows>
    </scene>
    <model name='link_velocity_demo'>
      <plugin name='set_link_velocity_plugin' filename='libSetLinkVelocityPlugin.so'/>
      <link name='white_link_0'>
        <pose frame=''>0 1 1 0 0 0</pose>
        <visual name='white_visual_0'>
          <geometry>
            <cylinder>
              <radius>0.1</radius>
              <length>0.5</length>
            </cylinder>
          </geometry>
          <material>
            <lighting>1</lighting>
            <script>
              <uri>file://media/materials/scripts/gazebo.material</uri>
              <name>Gazebo/White</name>
            </script>
          </material>
        </visual>
      </link>
      <link name='white_link_1'>
        <pose frame=''>0 0 1 0 0 0</pose>
        <visual name='white_visual_1'>
          <geometry>
            <cylinder>
              <radius>0.1</radius>
              <length>0.5</length>
            </cylinder>
          </geometry>
          <material>
            <lighting>1</lighting>
            <script>
              <uri>file://media/materials/scripts/gazebo.material</uri>
              <name>Gazebo/White</name>
            </script>
          </material>
        </visual>
      </link>
      <link name='white_link_2'>
        <pose frame=''>0 -1 1 0 0 0</pose>
        <visual name='white_visual_2'>
          <geometry>
            <cylinder>
              <radius>0.1</radius>
              <length>0.5</length>
            </cylinder>
          </geometry>
          <material>
            <lighting>1</lighting>
            <script>
              <uri>file://media/materials/scripts/gazebo.material</uri>
              <name>Gazebo/White</name>
            </script>
          </material>
        </visual>
      </link>
      <link name='red_link_0'>
        <pose frame=''>0 1 2 0 0 0</pose>
        <visual name='red_visual_1'>
          <geometry>
            <cylinder>
              <radius>0.1</radius>
              <length>0.5</length>
            </cylinder>
          </geometry>
          <material>
            <lighting>1</lighting>
            <script>
              <uri>file://media/materials/scripts/gazebo.material</uri>
              <name>Gazebo/Red</name>
            </script>
          </material>
        </visual>
      </link>
      <link name='red_link_1'>
        <pose frame=''>0 0 2 0 0 0</pose>
        <visual name='red_visual_1'>
          <geometry>
            <cylinder>
              <radius>0.1</radius>
              <length>0.5</length>
            </cylinder>
          </geometry>
          <material>
            <lighting>1</lighting>
            <script>
              <uri>file://media/materials/scripts/gazebo.material</uri>
              <name>Gazebo/Red</name>
            </script>
          </material>
        </visual>
      </link>
      <link name='red_link_2'>
        <pose frame=''>0 -1 2 0 0 0</pose>
        <visual name='red_visual_2'>
          <geometry>
            <cylinder>
              <radius>0.1</radius>
              <length>0.5</length>
            </cylinder>
          </geometry>
          <material>
            <lighting>1</lighting>
            <script>
              <uri>file://media/materials/scripts/gazebo.material</uri>
              <name>Gazebo/Red</name>
            </script>
          </material>
        </visual>
      </link>
      <link name='green_link_0'>
        <pose frame=''>0 1 3 0 0 0</pose>
        <visual name='green_visual_0'>
          <geometry>
            <cylinder>
              <radius>0.1</radius>
              <length>0.5</length>
            </cylinder>
          </geometry>
          <material>
            <lighting>1</lighting>
            <script>
              <uri>file://media/materials/scripts/gazebo.material</uri>
              <name>Gazebo/Green</name>
            </script>
          </material>
        </visual>
      </link>
      <link name='green_link_1'>
        <pose frame=''>0 0 3 0 0 0</pose>
        <visual name='green_visual_1'>
          <geometry>
            <cylinder>
              <radius>0.1</radius>
              <length>0.5</length>
            </cylinder>
          </geometry>
          <material>
            <lighting>1</lighting>
            <script>
              <uri>file://media/materials/scripts/gazebo.material</uri>
              <name>Gazebo/Green</name>
            </script>
          </material>
        </visual>
      </link>
      <link name='green_link_2'>
        <pose frame=''>0 -1 3 0 0 0</pose>
        <visual name='green_visual_2'>
          <geometry>
            <cylinder>
              <radius>0.1</radius>
              <length>0.5</length>
            </cylinder>
          </geometry>
          <material>
            <lighting>1</lighting>
            <script>
              <uri>file://media/materials/scripts/gazebo.material</uri>
              <name>Gazebo/Green</name>
            </script>
          </material>
        </visual>
      </link>
    </model>
    <model name='joint_velocity_demo'>
      <plugin name='set_joint_velocity_plugin' filename='libSetJointVelocityPlugin.so'/>
      <link name='purple_link_0'>
        <pose frame=''>0 -1 5 0 0 0</pose>
        <visual name='purple_visual_0'>
          <geometry>
            <cylinder>
              <radius>0.1</radius>
              <length>0.5</length>
            </cylinder>
          </geometry>
          <material>
            <lighting>1</lighting>
            <script>
              <uri>file://media/materials/scripts/gazebo.material</uri>
              <name>Gazebo/Purple</name>
            </script>
          </material>
        </visual>
      </link>
      <link name='purple_link_1'>
        <pose frame=''>0 -1 5.5 0 0 0</pose>
        <visual name='purple_visual_1'>
          <geometry>
            <cylinder>
              <radius>0.1</radius>
              <length>0.5</length>
            </cylinder>
          </geometry>
          <material>
            <lighting>1</lighting>
            <script>
              <uri>file://media/materials/scripts/gazebo.material</uri>
              <name>Gazebo/Purple</name>
            </script>
          </material>
        </visual>
      </link>
      <joint name='purple_joint' type='revolute'>
        <parent>purple_link_0</parent>
        <child>purple_link_1</child>
        <pose frame=''>0 0 -0.25 0 -0 0</pose>
        <axis>
          <xyz>1 0 0</xyz>
          <limit>
            <lower>-1.5</lower>
            <upper>1.5</upper>
            <effort>-1</effort>
            <velocity>-1</velocity>
          </limit>
        </axis>
      </joint>
      <link name='orange_link_0'>
        <pose frame=''>0 0 5 0 0 0</pose>
        <visual name='orange_visual_0'>
          <geometry>
            <cylinder>
              <radius>0.1</radius>
              <length>0.5</length>
            </cylinder>
          </geometry>
          <material>
            <lighting>1</lighting>
            <script>
              <uri>file://media/materials/scripts/gazebo.material</uri>
              <name>Gazebo/Orange</name>
            </script>
          </material>
        </visual>
      </link>
      <link name='orange_link_1'>
        <pose frame=''>0 0 5.5 0 0 0</pose>
        <visual name='orange_visual_1'>
          <geometry>
            <cylinder>
              <radius>0.1</radius>
              <length>0.5</length>
            </cylinder>
          </geometry>
          <material>
            <lighting>1</lighting>
            <script>
              <uri>file://media/materials/scripts/gazebo.material</uri>
              <name>Gazebo/Orange</name>
            </script>
          </material>
        </visual>
      </link>
      <joint name='orange_joint' type='revolute'>
        <parent>orange_link_0</parent>
        <child>orange_link_1</child>
        <pose frame=''>0 0 -0.25 0 -0 0</pose>
        <axis>
          <xyz>1 0 0</xyz>
          <limit>
            <lower>-1.5</lower>
            <upper>1.5</upper>
            <effort>-1</effort>
            <velocity>-1</velocity>
          </limit>
        </axis>
      </joint>
      <link name='gray_link_0'>
        <pose frame=''>0 1 5 0 0 0</pose>
        <visual name='gray_visual_0'>
          <geometry>
            <cylinder>
              <radius>0.1</radius>
              <length>0.5</length>
            </cylinder>
          </geometry>
          <material>
            <lighting>1</lighting>
            <script>
              <uri>file://media/materials/scripts/gazebo.material</uri>
              <name>Gazebo/Grey</name>
            </script>
          </material>
        </visual>
      </link>
      <link name='gray_link_1'>
        <pose frame=''>0 1 5.5 0 0 0</pose>
        <visual name='gray_visual_1'>
          <geometry>
            <cylinder>
              <radius>0.1</radius>
              <length>0.5</length>
            </cylinder>
          </geometry>
          <material>
            <lighting>1</lighting>
            <script>
              <uri>file://media/materials/scripts/gazebo.material</uri>
              <name>Gazebo/Grey</name>
            </script>
          </material>
        </visual>
      </link>
      <joint name='gray_joint' type='revolute'>
        <parent>gray_link_0</parent>
        <child>gray_link_1</child>
        <pose frame=''>0 0 -0.25 0 -0 0</pose>
        <axis>
          <xyz>1 0 0</xyz>
          <limit>
            <lower>-1.5</lower>
            <upper>1.5</upper>
            <effort>-1</effort>
            <velocity>-1</velocity>
          </limit>
        </axis>
      </joint>
    </model>
    <gui fullscreen='0'>
      <camera name='user_camera'>
        <pose frame=''>-10 0 3 0 0 0</pose>
        <view_controller>orbit</view_controller>
        <projection_type>perspective</projection_type>
      </camera>
    </gui>
  </world>

</sdf>
