<?xml version="1.0"?>
<sdf version="1.6">
  <world name="default">
    <physics name="default_physics" default="0" type="ode">
      <max_step_size>0.001</max_step_size>
      <real_time_factor>1</real_time_factor>
      <real_time_update_rate>1000</real_time_update_rate>
      <ode>
        <solver>
          <type>quick</type>
          <iters>50</iters>
          <sor>1.0</sor> <!-- Important, see issue #2209 -->
          <use_dynamic_moi_rescaling>false</use_dynamic_moi_rescaling>
        </solver>
      </ode>
    </physics>
    <include>
      <uri>model://ground_plane</uri>
    </include>
    <include>
      <uri>model://sun</uri>
    </include>
    <model name="model_1">
      <link name="link_1">
        <pose>0 0 2.0 0 0 0</pose>
        <inertial>
          <inertia>
            <ixx>0.100000</ixx>
            <ixy>0.000000</ixy>
            <ixz>0.000000</ixz>
            <iyy>0.100000</iyy>
            <iyz>0.000000</iyz>
            <izz>0.100000</izz>
          </inertia>
          <mass>10.000000</mass>
        </inertial>
        <visual name="visual_sphere">
          <geometry>
            <sphere>
              <radius>0.100000</radius>
            </sphere>
          </geometry>
        </visual>
        <visual name="visual_cylinder">
          <pose>0 0 -0.75 0 0 0</pose>
          <geometry>
            <cylinder>
              <radius>0.0100000</radius>
              <length>1.5</length>
            </cylinder>
          </geometry>
        </visual>
        <collision name="collision_sphere">
          <max_contacts>250</max_contacts>
          <geometry>
            <sphere>
              <radius>0.100000</radius>
            </sphere>
          </geometry>
        </collision>
      </link>
      <joint name="joint_01" type="revolute">
        <parent>world</parent>
        <child>link_1</child>
        <pose>0 0 -1.5 0 0 0</pose>
        <axis>
          <limit>
            <lower>-1.57079</lower>
            <upper>1.57079</upper>
          </limit>
          <dynamics>
            <damping>0.000000</damping>
            <friction>0.000000</friction>
          </dynamics>
          <xyz>1.000000 0.000000 0.000000</xyz>
        </axis>
        <sensor name="force_torque" type="force_torque">
          <update_rate>30</update_rate>
        </sensor>
      </joint>
    </model>
  </world>
</sdf>
