<?xml version="1.0" ?>

<sdf version="1.5">
  <model name="four_bar_sdf">
    <pose>0 0 0.04  0 0 0</pose>
    <self_collide>true</self_collide>

    <link name="link_AB">
      <pose>-0.01 -0.15000000000000002 0  0 0 0</pose>
      <inertial>
        <mass>0.07200000000000001</mass>
        <inertia>
          <ixx>0.0005424000000000002</ixx>
          <iyy>4.800000000000001e-06</iyy>
          <izz>0.0005424000000000002</izz>
          <ixy></ixy>
          <ixz></ixz>
          <iyz></iyz>
        </inertia>
      </inertial>
      <collision name="boxABCollision">
        <geometry>
          <box>
            <size>0.02 0.30000000000000004 0.02</size>
          </box>
        </geometry>
      </collision>
      <visual name="boxABVisual">
        <geometry>
          <box>
            <size>0.02 0.30000000000000004 0.02</size>
          </box>
        </geometry>
        <material>
          <script>
            <uri>file://media/materials/scripts/gazebo.material</uri>
            <name>Gazebo/Wood</name>
          </script>
        </material>
      </visual>
    </link>

    <link name="link_BE">
      <pose>0.05 -0.31000000000000005 0  0 0 0</pose>
      <inertial>
        <mass>0.024</mass>
        <inertia>
          <ixx>1.6000000000000001e-06</ixx>
          <iyy>2.0800000000000004e-05</iyy>
          <izz>2.0800000000000004e-05</izz>
          <ixy></ixy>
          <ixz></ixz>
          <iyz></iyz>
        </inertia>
      </inertial>
      <collision name="boxBECollision">
        <geometry>
          <box>
            <size>0.1 0.02 0.02</size>
          </box>
        </geometry>
      </collision>
      <visual name="boxBEVisual">
        <geometry>
          <box>
            <size>0.1 0.02 0.02</size>
          </box>
        </geometry>
        <material>
          <script>
            <uri>file://media/materials/scripts/gazebo.material</uri>
            <name>Gazebo/Wood</name>
          </script>
        </material>
      </visual>
    </link>

    <link name="link_EC">
      <pose>0.15000000000000002 -0.31000000000000005 0  0 0 0</pose>
      <inertial>
        <mass>0.024</mass>
        <inertia>
          <ixx>1.6000000000000001e-06</ixx>
          <iyy>2.0800000000000004e-05</iyy>
          <izz>2.0800000000000004e-05</izz>
          <ixy></ixy>
          <ixz></ixz>
          <iyz></iyz>
        </inertia>
      </inertial>
      <collision name="boxECCollision">
        <geometry>
          <box>
            <size>0.1 0.02 0.02</size>
          </box>
        </geometry>
      </collision>
      <visual name="boxECVisual">
        <geometry>
          <box>
            <size>0.1 0.02 0.02</size>
          </box>
        </geometry>
        <material>
          <script>
            <uri>file://media/materials/scripts/gazebo.material</uri>
            <name>Gazebo/Wood</name>
          </script>
        </material>
      </visual>
    </link>

    <link name="link_CD">
      <pose>0.21000000000000002 -0.15000000000000002 0  0 0 0</pose>
      <inertial>
        <mass>0.07200000000000001</mass>
        <inertia>
          <ixx>0.0005424000000000002</ixx>
          <iyy>4.800000000000001e-06</iyy>
          <izz>0.0005424000000000002</izz>
          <ixy></ixy>
          <ixz></ixz>
          <iyz></iyz>
        </inertia>
      </inertial>
      <collision name="boxCDCollision">
        <geometry>
          <box>
            <size>0.02 0.30000000000000004 0.02</size>
          </box>
        </geometry>
      </collision>
      <visual name="boxCDVisual">
        <geometry>
          <box>
            <size>0.02 0.30000000000000004 0.02</size>
          </box>
        </geometry>
        <material>
          <script>
            <uri>file://media/materials/scripts/gazebo.material</uri>
            <name>Gazebo/Wood</name>
          </script>
        </material>
      </visual>
    </link>

    <joint name="joint_A" type="revolute">
      <pose>0.01 0.15000000000000002 0 0 0 0</pose>
      <parent>world</parent>
      <child>link_AB</child>

      <axis>
        <xyz>0 0 1</xyz>
      </axis>

    </joint>

    <joint name="joint_B" type="revolute">
      <pose>-0.05 0.01 0 0 0 0</pose>
      <parent>link_AB</parent>
      <child>link_BE</child>

      <axis>
        <xyz>0 0 1</xyz>
      </axis>

    </joint>

    <joint name="joint_D" type="revolute">
      <pose>-0.01 0.15000000000000002 0 0 0 0</pose>
      <parent>world</parent>
      <child>link_CD</child>

      <axis>
        <xyz>0 0 1</xyz>
      </axis>

    </joint>

    <joint name="joint_C" type="revolute">
      <pose>0.05 0.01 0 0 0 0</pose>
      <parent>link_CD</parent>
      <child>link_EC</child>

      <axis>
        <xyz>0 0 1</xyz>
      </axis>

    </joint>

    <joint name="joint_E" type="fixed">
      <pose>-0.05 0 0 0 0 0</pose>
      <parent>link_BE</parent>
      <child>link_EC</child>

    </joint>

  </model>
</sdf>
